{"trial_id": "0002", "hyperparameters": {"space": [{"class_name": "Int", "config": {"name": "lstm_units", "default": null, "conditions": [], "min_value": 32, "max_value": 128, "step": 32, "sampling": "linear"}}, {"class_name": "Boolean", "config": {"name": "use_bidirectional", "default": false, "conditions": []}}, {"class_name": "Float", "config": {"name": "learning_rate", "default": 0.0001, "conditions": [], "min_value": 0.0001, "max_value": 0.01, "step": null, "sampling": "log"}}], "values": {"lstm_units": 96, "use_bidirectional": true, "learning_rate": 0.0040812671360801476, "tuner/epochs": 2, "tuner/initial_epoch": 0, "tuner/bracket": 2, "tuner/round": 0}}, "metrics": {"metrics": {}}, "score": null, "best_step": 0, "status": "FAILED", "message": "Traceback (most recent call last):\n  File \"d:\\Projects\\customer_churn\\venv\\lib\\site-packages\\keras_tuner\\src\\engine\\base_tuner.py\", line 274, in _try_run_and_update_trial\n    self._run_and_update_trial(trial, *fit_args, **fit_kwargs)\n  File \"d:\\Projects\\customer_churn\\venv\\lib\\site-packages\\keras_tuner\\src\\engine\\base_tuner.py\", line 239, in _run_and_update_trial\n    results = self.run_trial(trial, *fit_args, **fit_kwargs)\n  File \"d:\\Projects\\customer_churn\\venv\\lib\\site-packages\\keras_tuner\\src\\tuners\\hyperband.py\", line 427, in run_trial\n    return super().run_trial(trial, *fit_args, **fit_kwargs)\n  File \"d:\\Projects\\customer_churn\\venv\\lib\\site-packages\\keras_tuner\\src\\engine\\tuner.py\", line 314, in run_trial\n    obj_value = self._build_and_fit_model(trial, *args, **copied_kwargs)\n  File \"d:\\Projects\\customer_churn\\venv\\lib\\site-packages\\keras_tuner\\src\\engine\\tuner.py\", line 233, in _build_and_fit_model\n    results = self.hypermodel.fit(hp, model, *args, **kwargs)\n  File \"d:\\Projects\\customer_churn\\venv\\lib\\site-packages\\keras_tuner\\src\\engine\\hypermodel.py\", line 149, in fit\n    return model.fit(*args, **kwargs)\n  File \"d:\\Projects\\customer_churn\\venv\\lib\\site-packages\\keras\\src\\utils\\traceback_utils.py\", line 70, in error_handler\n    raise e.with_traceback(filtered_tb) from None\n  File \"C:\\Users\\TAHARA~1\\AppData\\Local\\Temp\\__autograph_generated_file8fv2yp3u.py\", line 15, in tf__train_function\n    retval_ = ag__.converted_call(ag__.ld(step_function), (ag__.ld(self), ag__.ld(iterator)), None, fscope)\nValueError: in user code:\n\n    File \"d:\\Projects\\customer_churn\\venv\\lib\\site-packages\\keras\\src\\engine\\training.py\", line 1338, in train_function  *\n        return step_function(self, iterator)\n    File \"d:\\Projects\\customer_churn\\venv\\lib\\site-packages\\keras\\src\\engine\\training.py\", line 1322, in step_function  **\n        outputs = model.distribute_strategy.run(run_step, args=(data,))\n    File \"d:\\Projects\\customer_churn\\venv\\lib\\site-packages\\keras\\src\\engine\\training.py\", line 1303, in run_step  **\n        outputs = model.train_step(data)\n    File \"d:\\Projects\\customer_churn\\venv\\lib\\site-packages\\keras\\src\\engine\\training.py\", line 1080, in train_step\n        y_pred = self(x, training=True)\n    File \"d:\\Projects\\customer_churn\\venv\\lib\\site-packages\\keras\\src\\utils\\traceback_utils.py\", line 70, in error_handler\n        raise e.with_traceback(filtered_tb) from None\n    File \"d:\\Projects\\customer_churn\\venv\\lib\\site-packages\\keras\\src\\engine\\input_spec.py\", line 235, in assert_input_compatibility\n        raise ValueError(\n\n    ValueError: Exception encountered when calling layer 'sequential' (type Sequential).\n    \n    Input 0 of layer \"bidirectional\" is incompatible with the layer: expected ndim=3, found ndim=2. Full shape received: (32, 13)\n    \n    Call arguments received by layer 'sequential' (type Sequential):\n      \u2022 inputs=tf.Tensor(shape=(32, 13), dtype=float32)\n      \u2022 training=True\n      \u2022 mask=None\n\n"}